[42.136669159] 2019-10-12 21:12:06,092 - INFO - launcher: Starting sanity checks
[42.136669159] 2019-10-12 21:12:06,092 - INFO - launcher: Checking for Python 3.5+
[42.136669159] 2019-10-12 21:12:06,092 - INFO - launcher: Checking console encoding
[42.136669159] 2019-10-12 21:12:06,092 - INFO - launcher: Setting console encoding to UTF-8
[43.165922165] 2019-10-12 21:12:06,093 - INFO - launcher: Ensuring we're in the right environment
[44.762372971] 2019-10-12 21:12:06,095 - INFO - launcher: Adding local bins/ folder to path
[559.198617935] 2019-10-12 21:12:06,609 - INFO - launcher: Required checks passed.
[562.128543854] 2019-10-12 21:12:06,612 - INFO - launcher: Optional checks passed.
[562.495946884] 2019-10-12 21:12:06,613 - INFO - launcher: Moving old musicbot log

######################### PRE-RUN SANITY CHECKS PASSED #########################

[1.4948399066925049] 2019-10-12 21:12:07,545 - WARNING - musicbot.config | In config.py::MainThread(13384), line 121 in run_checks: i18n file does not exist. Trying to fallback to config/i18n/en.json.
[1.4958338737487793] 2019-10-12 21:12:07,546 - INFO - musicbot.config | In config.py::MainThread(13384), line 132 in run_checks: Using i18n: config/i18n/en.json
[1.4976670742034912] 2019-10-12 21:12:07,548 - DEBUG - musicbot.bot | In bot.py::MainThread(13384), line 225 in _setup_logging: Set logging level to INFO
[1.4996187686920166] 2019-10-12 21:12:07,550 - DEBUG - musicbot.json | In json.py::MainThread(13384), line 8 in __init__: Init JSON obj with config/i18n/en.json
[1.5821301937103271] 2019-10-12 21:12:07,632 - INFO - musicbot.bot | In bot.py::MainThread(13384), line 90 in __init__: Starting MusicBot version_unknown
[1.5821301937103271] 2019-10-12 21:12:07,632 - INFO - musicbot.bot | In bot.py::MainThread(13384), line 96 in __init__: Loaded autoplaylist with 2531 entries
[10.6216833591461182] 2019-10-12 21:12:16,672 - DEBUG - musicbot.bot | In bot.py::MainThread(13384), line 951 in on_ready: Connection established, ready to go.
[10.6216833591461182] 2019-10-12 21:12:16,672 - DEBUG - musicbot.bot | In bot.py::MainThread(13384), line 342 in _cache_app_info: Caching app info
[10.7502114772796631] 2019-10-12 21:12:16,800 - DEBUG - musicbot.bot | In bot.py::MainThread(13384), line 773 in _scheck_ensure_env: Ensuring data folders exist
[10.7525501251220703] 2019-10-12 21:12:16,803 - DEBUG - musicbot.bot | In bot.py::MainThread(13384), line 783 in _scheck_ensure_env: Deleted old audio cache
[10.7525501251220703] 2019-10-12 21:12:16,803 - DEBUG - musicbot.bot | In bot.py::MainThread(13384), line 789 in _scheck_server_permissions: Checking server permissions
[10.7525501251220703] 2019-10-12 21:12:16,803 - DEBUG - musicbot.bot | In bot.py::MainThread(13384), line 793 in _scheck_autoplaylist: Auditing autoplaylist
[10.7531039714813232] 2019-10-12 21:12:16,803 - DEBUG - musicbot.bot | In bot.py::MainThread(13384), line 797 in _scheck_configs: Validating config
[10.7531039714813232] 2019-10-12 21:12:16,803 - DEBUG - musicbot.config | In config.py::MainThread(13384), line 236 in async_validate: Validating options...
[10.7531039714813232] 2019-10-12 21:12:16,803 - DEBUG - musicbot.bot | In bot.py::MainThread(13384), line 800 in _scheck_configs: Validating permissions config
[10.7531039714813232] 2019-10-12 21:12:16,803 - DEBUG - musicbot.permissions | In permissions.py::MainThread(13384), line 94 in async_validate: Validating permissions...
[10.7531039714813232] 2019-10-12 21:12:16,803 - INFO - musicbot.bot | In bot.py::MainThread(13384), line 968 in on_ready: Connected: 632760101043830784/KHrmastic#3624
[10.7540979385375977] 2019-10-12 21:12:16,804 - INFO - musicbot.bot | In bot.py::MainThread(13384), line 976 in on_ready: Owner:     361607957227765761/Da Quite#0525

[10.7545177936553955] 2019-10-12 21:12:16,805 - INFO - musicbot.bot | In bot.py::MainThread(13384), line 979 in on_ready: Guild List:
[10.7550561428070068] 2019-10-12 21:12:16,805 - INFO - musicbot.bot | In bot.py::MainThread(13384), line 983 in on_ready:  - Kawaii Team
[10.7550561428070068] 2019-10-12 21:12:16,805 - INFO - musicbot.bot | In bot.py::MainThread(13384), line 983 in on_ready:  - Bad Day Huh?
[10.7560319900512695] 2019-10-12 21:12:16,806 - INFO - musicbot.bot | In bot.py::MainThread(13384), line 1039 in on_ready: Not bound to any text channels
[10.7573759555816650] 2019-10-12 21:12:16,807 - INFO - musicbot.bot | In bot.py::MainThread(13384), line 1065 in on_ready: Not autojoining any voice channels
[19.6624190807342529] 2019-10-12 21:12:25,712 - INFO - musicbot.bot | In bot.py::MainThread(13384), line 2706 in on_message: 361607957227765761/Da Quite#0525: .p lan cuoi
[19.6636183261871338] 2019-10-12 21:12:25,714 - ERROR - musicbot.bot | In bot.py::MainThread(13384), line 2835 in on_message: Error in play: CommandError: The bot is not in a voice channel.  Use .summon to summon it to your voice channel.
Traceback (most recent call last):
  File "C:\Users\khiet\Desktop\Music Discord bot\MusicBot\musicbot\bot.py", line 2734, in on_message
    handler_kwargs['player'] = await self.get_player(message.channel)
  File "C:\Users\khiet\Desktop\Music Discord bot\MusicBot\musicbot\bot.py", line 433, in get_player
    'Use %ssummon to summon it to your voice channel.' % self.config.command_prefix)
musicbot.exceptions.CommandError: The bot is not in a voice channel.  Use .summon to summon it to your voice channel.
[23.5010001659393311] 2019-10-12 21:12:29,551 - INFO - musicbot.bot | In bot.py::MainThread(13384), line 2706 in on_message: 361607957227765761/Da Quite#0525: .summon
[25.2081089019775391] 2019-10-12 21:12:31,258 - DEBUG - musicbot.bot | In bot.py::MainThread(13384), line 733 in deserialize_queue: Deserializing queue for 458220873556426765
[25.4171259403228760] 2019-10-12 21:12:31,467 - DEBUG - musicbot.bot | In bot.py::MainThread(13384), line 425 in get_player: Created player via deserialization for guild 458220873556426765 with 1 entries
[25.4171259403228760] 2019-10-12 21:12:31,467 - INFO - musicbot.bot | In bot.py::MainThread(13384), line 1935 in cmd_summon: Joining Bad Day Huh?/just cry....
[25.4205751419067383] 2019-10-12 21:12:31,471 - DEBUG - musicbot.entry | In entry.py::MainThread(13384), line 56 in get_ready_future: Created future for None
[25.4222121238708496] 2019-10-12 21:12:31,472 - INFO - musicbot.entry | In entry.py::MainThread(13384), line 292 in _really_download: Download started: https://www.youtube.com/watch?v=kSjj0LlsqnI
[27.8156714439392090] 2019-10-12 21:12:33,866 - INFO - musicbot.bot | In bot.py::MainThread(13384), line 2706 in on_message: 361607957227765761/Da Quite#0525: .p lan cuoi
[31.7029345035552979] 2019-10-12 21:12:37,753 - DEBUG - musicbot.bot | In bot.py::MainThread(13384), line 1408 in cmd_play: {'_type': 'url', 'url': 'ytsearch:lan cuoi', 'ie_key': None, 'extractor': 'generic', 'webpage_url': 'lan cuoi', 'webpage_url_basename': 'lan cuoi', 'extractor_key': 'Generic'}
[39.4064629077911377] 2019-10-12 21:12:45,456 - DEBUG - musicbot.entry | In entry.py::MainThread(13384), line 56 in get_ready_future: Created future for None
[39.4074389934539795] 2019-10-12 21:12:45,457 - DEBUG - musicbot.bot | In bot.py::MainThread(13384), line 624 in on_player_entry_added: Running on_player_entry_added
[39.4074389934539795] 2019-10-12 21:12:45,457 - DEBUG - musicbot.bot | In bot.py::MainThread(13384), line 709 in serialize_queue: Serializing queue for 458220873556426765
[39.4087474346160889] 2019-10-12 21:12:45,459 - INFO - musicbot.entry | In entry.py::MainThread(13384), line 292 in _really_download: Download started: https://www.youtube.com/watch?v=kSjj0LlsqnI
[48.0411059856414795] 2019-10-12 21:12:54,091 - INFO - musicbot.bot | In bot.py::MainThread(13384), line 2706 in on_message: 391830785180827649/bill ur pill#2074: .q
[80.2293546199798584] 2019-10-12 21:13:26,279 - INFO - musicbot.bot | In bot.py::MainThread(13384), line 2706 in on_message: 361607957227765761/Da Quite#0525: .p yeu 5
[80.2329094409942627] 2019-10-12 21:13:26,283 - INFO - musicbot.entry | In entry.py::MainThread(13384), line 302 in _really_download: Download complete: https://www.youtube.com/watch?v=kSjj0LlsqnI
[80.2777647972106934] 2019-10-12 21:13:26,328 - WARNING - musicbot.player | In player.py::MainThread(13384), line 274 in _play: Failed to get entry, retrying
Traceback (most recent call last):
  File "C:\Users\khiet\AppData\Local\Programs\Python\Python37-32\lib\site-packages\youtube_dl\downloader\common.py", line 202, in try_rename
    os.rename(encodeFilename(old_filename), encodeFilename(new_filename))
PermissionError: [WinError 32] The process cannot access the file because it is being used by another process: 'audio_cache\\youtube-kSjj0LlsqnI-L_N_CU_I_i_ben_em_xot_xa_ng_i_i.webm.part' -> 'audio_cache\\youtube-kSjj0LlsqnI-L_N_CU_I_i_ben_em_xot_xa_ng_i_i.webm'

During handling of the above exception, another exception occurred:

Traceback (most recent call last):
  File "C:\Users\khiet\Desktop\Music Discord bot\MusicBot\musicbot\entry.py", line 297, in _really_download
    result = await self.playlist.downloader.extract_info(self.playlist.loop, self.url, download=True)
  File "C:\Users\khiet\Desktop\Music Discord bot\MusicBot\musicbot\downloader.py", line 84, in extract_info
    return await loop.run_in_executor(self.thread_pool, functools.partial(self.unsafe_ytdl.extract_info, *args, **kwargs))
  File "C:\Users\khiet\AppData\Local\Programs\Python\Python37-32\lib\concurrent\futures\thread.py", line 57, in run
    result = self.fn(*self.args, **self.kwargs)
  File "C:\Users\khiet\AppData\Local\Programs\Python\Python37-32\lib\site-packages\youtube_dl\YoutubeDL.py", line 807, in extract_info
    return self.process_ie_result(ie_result, download, extra_info)
  File "C:\Users\khiet\AppData\Local\Programs\Python\Python37-32\lib\site-packages\youtube_dl\YoutubeDL.py", line 862, in process_ie_result
    return self.process_video_result(ie_result, download=download)
  File "C:\Users\khiet\AppData\Local\Programs\Python\Python37-32\lib\site-packages\youtube_dl\YoutubeDL.py", line 1643, in process_video_result
    self.process_info(new_info)
  File "C:\Users\khiet\AppData\Local\Programs\Python\Python37-32\lib\site-packages\youtube_dl\YoutubeDL.py", line 1925, in process_info
    success = dl(filename, info_dict)
  File "C:\Users\khiet\AppData\Local\Programs\Python\Python37-32\lib\site-packages\youtube_dl\YoutubeDL.py", line 1864, in dl
    return fd.download(name, info)
  File "C:\Users\khiet\AppData\Local\Programs\Python\Python37-32\lib\site-packages\youtube_dl\downloader\common.py", line 366, in download
    return self.real_download(filename, info_dict)
  File "C:\Users\khiet\AppData\Local\Programs\Python\Python37-32\lib\site-packages\youtube_dl\downloader\http.py", line 342, in real_download
    return download()
  File "C:\Users\khiet\AppData\Local\Programs\Python\Python37-32\lib\site-packages\youtube_dl\downloader\http.py", line 323, in download
    self.try_rename(ctx.tmpfilename, ctx.filename)
  File "C:\Users\khiet\AppData\Local\Programs\Python\Python37-32\lib\site-packages\youtube_dl\downloader\common.py", line 204, in try_rename
    self.report_error('unable to rename file: %s' % error_to_compat_str(err))
  File "C:\Users\khiet\AppData\Local\Programs\Python\Python37-32\lib\site-packages\youtube_dl\downloader\common.py", line 165, in report_error
    self.ydl.report_error(*args, **kargs)
  File "C:\Users\khiet\AppData\Local\Programs\Python\Python37-32\lib\site-packages\youtube_dl\YoutubeDL.py", line 624, in report_error
    self.trouble(error_message, tb)
  File "C:\Users\khiet\AppData\Local\Programs\Python\Python37-32\lib\site-packages\youtube_dl\YoutubeDL.py", line 594, in trouble
    raise DownloadError(message, exc_info)
youtube_dl.utils.DownloadError: ERROR: unable to rename file: [WinError 32] The process cannot access the file because it is being used by another process: 'audio_cache\\youtube-kSjj0LlsqnI-L_N_CU_I_i_ben_em_xot_xa_ng_i_i.webm.part' -> 'audio_cache\\youtube-kSjj0LlsqnI-L_N_CU_I_i_ben_em_xot_xa_ng_i_i.webm'

During handling of the above exception, another exception occurred:

Traceback (most recent call last):
  File "C:\Users\khiet\Desktop\Music Discord bot\MusicBot\musicbot\player.py", line 272, in _play
    entry = await self.playlist.get_next_entry()
  File "C:\Users\khiet\Desktop\Music Discord bot\MusicBot\musicbot\playlist.py", line 334, in get_next_entry
    return await entry.get_ready_future()
  File "C:\Users\khiet\Desktop\Music Discord bot\MusicBot\musicbot\entry.py", line 217, in _download
    await self._really_download()
  File "C:\Users\khiet\Desktop\Music Discord bot\MusicBot\musicbot\entry.py", line 300, in _really_download
    raise ExtractionError(e)
musicbot.exceptions.ExtractionError: ERROR: unable to rename file: [WinError 32] The process cannot access the file because it is being used by another process: 'audio_cache\\youtube-kSjj0LlsqnI-L_N_CU_I_i_ben_em_xot_xa_ng_i_i.webm.part' -> 'audio_cache\\youtube-kSjj0LlsqnI-L_N_CU_I_i_ben_em_xot_xa_ng_i_i.webm'
[80.2891118526458740] 2019-10-12 21:13:26,339 - DEBUG - musicbot.entry | In entry.py::MainThread(13384), line 56 in get_ready_future: Created future for audio_cache\youtube-kSjj0LlsqnI-L_N_CU_I_i_ben_em_xot_xa_ng_i_i.webm
[80.2900879383087158] 2019-10-12 21:13:26,340 - FFMPEG - musicbot.player | In player.py::MainThread(13384), line 293 in _play: Creating player with options: -nostdin -vn audio_cache\youtube-kSjj0LlsqnI-L_N_CU_I_i_ben_em_xot_xa_ng_i_i.webm
[80.2930157184600830] 2019-10-12 21:13:26,343 - DEBUG - musicbot.player | In player.py::MainThread(13384), line 306 in _play: Playing <musicbot.player.SourcePlaybackCounter object at 0x05A96CD0> using <discord.voice_client.VoiceClient object at 0x053D5430>
[80.2959446907043457] 2019-10-12 21:13:26,346 - DEBUG - musicbot.bot | In bot.py::MainThread(13384), line 460 in on_player_play: Running on_player_play
[80.3086171150207520] 2019-10-12 21:13:26,359 - INFO - musicbot.bot | In bot.py::MainThread(13384), line 2706 in on_message: 391830785180827649/bill ur pill#2074: .resume
[80.3116846084594727] 2019-10-12 21:13:26,362 - ERROR - musicbot.bot | In bot.py::MainThread(13384), line 2835 in on_message: Error in resume: PermissionsError: You don't have permission to use that command.
Reason: This command is not enabled for your group (Default).
Traceback (most recent call last):
  File "C:\Users\khiet\Desktop\Music Discord bot\MusicBot\musicbot\bot.py", line 2788, in on_message
    expire_in=20)
musicbot.exceptions.PermissionsError: This command is not enabled for your group (Default).
[80.3149843215942383] 2019-10-12 21:13:26,365 - INFO - musicbot.bot | In bot.py::MainThread(13384), line 2706 in on_message: 361607957227765761/Da Quite#0525: .option
[81.5308947563171387] 2019-10-12 21:13:27,581 - DEBUG - musicbot.bot | In bot.py::MainThread(13384), line 3004 in on_guild_available: Guild "Bad Day Huh?" has become available.
[81.5316088199615479] 2019-10-12 21:13:27,582 - DEBUG - musicbot.bot | In bot.py::MainThread(13384), line 3004 in on_guild_available: Guild "Kawaii Team" has become available.
[82.6785979270935059] 2019-10-12 21:13:28,729 - DEBUG - musicbot.bot | In bot.py::MainThread(13384), line 1408 in cmd_play: {'_type': 'url', 'url': 'ytsearch:yeu 5', 'ie_key': None, 'extractor': 'generic', 'webpage_url': 'yeu 5', 'webpage_url_basename': 'yeu 5', 'extractor_key': 'Generic'}
[83.5378420352935791] 2019-10-12 21:13:29,588 - DEBUG - musicbot.bot | In bot.py::MainThread(13384), line 951 in on_ready: Connection established, ready to go.
[83.5381290912628174] 2019-10-12 21:13:29,588 - DEBUG - musicbot.bot | In bot.py::MainThread(13384), line 956 in on_ready: Received additional READY event, may have failed to resume
[87.6759812831878662] 2019-10-12 21:13:33,726 - DEBUG - musicbot.entry | In entry.py::MainThread(13384), line 56 in get_ready_future: Created future for None
[87.6771793365478516] 2019-10-12 21:13:33,727 - DEBUG - musicbot.bot | In bot.py::MainThread(13384), line 624 in on_player_entry_added: Running on_player_entry_added
[87.6779630184173584] 2019-10-12 21:13:33,728 - DEBUG - musicbot.bot | In bot.py::MainThread(13384), line 709 in serialize_queue: Serializing queue for 458220873556426765
[87.6779630184173584] 2019-10-12 21:13:33,728 - INFO - musicbot.entry | In entry.py::MainThread(13384), line 292 in _really_download: Download started: https://www.youtube.com/watch?v=y576-ONm5II
[94.5489935874938965] 2019-10-12 21:13:40,599 - INFO - musicbot.entry | In entry.py::MainThread(13384), line 302 in _really_download: Download complete: https://www.youtube.com/watch?v=y576-ONm5II
[111.2005884647369385] 2019-10-12 21:13:57,251 - INFO - musicbot.bot | In bot.py::MainThread(13384), line 2706 in on_message: 361607957227765761/Da Quite#0525: .shutdown
[111.763887644] launcher-INFO: All done.
